Workbook

Sheet ЗАЯВКА НА ЧЕКИ
A1: Кликните по этой ячейке и скачайте файл "порядок работы" с инструкцией по заполнению данной заявки
A3: № чека | B3: Номенклатура (товары или услуги) | D3: Кол-во товара | F3: Общая | H3: Нужен ли номер | I3: Выберите нашу компанию
C4: Единица | E4: Цена за | F4: сумма | H4: счёта-фатуры? | J4: Название вашего ИП/ООО
C5: измерения | E5: единицу | F5: за товар | G5: Дата чека | H5: (предоставляется | J5: (для вашего контроля,
C6: товара | E6: товара | F6: или | H6: за дополнительую | J6: не указывается в чеке)
F7: услугу | H7: плату)
A8: 1 | B8: Пропишите нужную вам номенклатуру | C8: шт | D8: 1 | E8: 15000.15 | F8: =E8*D8 -> 15000.15 | G8: =VLOOKUP(I8,'СПИСОК ЧЕКОВЫХ КОМПАНИЙ'!A:C,3,0) -> 45643 | H8: Да | I8: с НДС 4 кв. 2024: ООО "Акцент" (с/ф возможна только от другой компании)
F9: =E9*D9 -> 0
F10: =E10*D10 -> 0
F11: =E11*D11 -> 0
F12: =E12*D12 -> 0
A13: Итоговая сумма чека: | F13: =SUM(F8:F12) -> 15000.15
A15: № чека | B15: Номенклатура (товары или услуги) | D15: Кол-во товара | F15: Общая | H15: Нужен ли номер | I15: Выберите нашу компанию
C16: Единица | E16: Цена за | F16: сумма | H16: счёта-фатуры? | J16: Название вашего ИП/ООО
C17: измерения | E17: единицу | F17: за товар | G17: Дата чека | H17: (предоставляется | J17: (для вашего контроля,
C18: товара | E18: товара | F18: или | H18: за дополнительую | J18: не указывается в чеке)
F19: услугу | H19: плату)
A20: 2 | B20: Пропишите нужную вам номенклатуру | C20: шт | D20: 1 | E20: 15000.15 | F20: =E20*D20 -> 15000.15 | G20: =VLOOKUP(I20,'СПИСОК ЧЕКОВЫХ КОМПАНИЙ'!A:C,3,0) -> 45607 | H20: Да | I20: с НДС 4 кв. 2024: ООО "Шпатл-Инко" (с/ф возможна только от другой компании)
F21: =E21*D21 -> 0
F22: =E22*D22 -> 0
F23: =E23*D23 -> 0
F24: =E24*D24 -> 0
A25: Итоговая сумма чека: | F25: =SUM(F20:F24) -> 15000.15
A27: № чека | B27: Номенклатура (товары или услуги) | D27: Кол-во товара | F27: Общая | H27: Нужен ли номер | I27: Выберите нашу компанию
C28: Единица | E28: Цена за | F28: сумма | H28: счёта-фатуры? | J28: Название вашего ИП/ООО
C29: измерения | E29: единицу | F29: за товар | G29: Дата чека | H29: (предоставляется | J29: (для вашего контроля,
C30: товара | E30: товара | F30: или | H30: за дополнительую | J30: не указывается в чеке)
F31: услугу | H31: плату)
A32: 3 | B32: Пропишите нужную вам номенклатуру | C32: шт | D32: 1 | E32: 15000.15 | F32: =E32*D32 -> 15000.15 | G32: =VLOOKUP(I32,'СПИСОК ЧЕКОВЫХ КОМПАНИЙ'!A:C,3,0) -> 45572 | H32: Да | I32: без НДС 4 кв. 2024: ООО "ГиперДрайв"
F33: =E33*D33 -> 0
F34: =E34*D34 -> 0
F35: =E35*D35 -> 0
F36: =E36*D36 -> 0
A37: Итоговая сумма чека: | F37: =SUM(F32:F36) -> 15000.15
A39: № чека | B39: Номенклатура (товары или услуги) | D39: Кол-во товара | F39: Общая | H39: Нужен ли номер | I39: Выберите нашу компанию
C40: Единица | E40: Цена за | F40: сумма | H40: счёта-фатуры? | J40: Название вашего ИП/ООО
C41: измерения | E41: единицу | F41: за товар | G41: Дата чека | H41: (предоставляется | J41: (для вашего контроля,
C42: товара | E42: товара | F42: или | H42: за дополнительую | J42: не указывается в чеке)
F43: услугу | H43: плату)
A44: 4 | B44: Пропишите нужную вам номенклатуру | C44: шт | D44: 1 | E44: 15000.15 | F44: =E44*D44 -> 15000.15 | G44: =VLOOKUP(I44,'СПИСОК ЧЕКОВЫХ КОМПАНИЙ'!A:C,3,0) -> 45534 | H44: Да | I44: с НДС 3 кв. 2024: ООО "Томса" (с/ф возможна только от другой компании)
...

Sheet СПИСОК ЧЕКОВЫХ КОМПАНИЙ
A1: Название компании, с НДС /без НДС | B1: ИНН | C1: Выбиваемые даты на сегодня | D1: ОКВЭДы компаний
A2: с НДС 1 кв. 2024: ООО "Бригант" (с/ф возможна только от другой компании) | B2: 7743348263 | C2: 45311 | D2: 41.20 Строительство жилых и нежилых зданий, 01.11.19 Выращивание прочих зерновых культур, 01.12 Выращивание риса, 01.29 Выращивание прочих многолетних культур, 01.61 Предоставление услуг в области растениеводства, 01.63 Деятельность сельскохозяйственная после сбора урожая, 25.12 Производство металлических дверей и окон, 33.14 Ремонт электрического оборудования, 33.20 Монтаж промышленных машин и оборудования, 35.12.2 Технологическое присоединение к распределительным электросетям, 38.11 Сбор неопасных отходов, 38.12 Сбор опасных отходов, 38.21 Обработка и утилизация неопасных отходов, 38.22 Обработка и утилизация опасных отходов, 41.10 Разработка строительных проектов, 42.22.2 Строительство местных линий электропередачи и связи, 43.11 Разборка и снос зданий, 43.12 Подготовка строительной площадки, 43.21 Производство электромонтажных работ, 43.22 Производство санитарно-технических работ, монтаж отопительных систем и систем кондиционирования воздуха, 43.29 Производство прочих строительно-монтажных работ, 43.99.5 Работы по монтажу стальных строительных конструкций, 43.99.7 Работы по сборке и монтажу сборных конструкций, 45.31.2 Деятельность агентов по оптовой торговле автомобильными деталями, узлами и принадлежностями, 46.13 Деятельность агентов по оптовой торговле лесоматериалами и строительными материалами, 46.49.33 Торговля оптовая писчебумажными и канцелярскими товарами, 46.65 Торговля оптовая офисной мебелью, 46.66 Торговля оптовая прочей офисной техникой и оборудованием, 46.69 Торговля оптовая прочими машинами и оборудованием, 46.71 Торговля оптовая твердым, жидким и газообразным топливом и подобными продуктами, 46.71.9 Торговля оптовая прочим топливом и подобными продуктами, 46.73 Торговля оптовая лесоматериалами, строительными материалами и санитарно-техническим оборудованием, 47.91.2 Торговля розничная, осуществляемая непосредственно при помощи информационно-коммуникационной сети Интернет, 49.20.9 Перевозка прочих грузов, 49.41 Деятельность автомобильного грузового транспорта, 49.42 Предоставление услуг по перевозкам, 53.20.31 Деятельность по курьерской доставке различными видами транспорта, 62.01 Разработка компьютерного программного обеспечения, 62.02 Деятельность консультативная и работы в области компьютерных технологий, 63.11 Деятельность по обработке данных, предоставление услуг по размещению информации и связанная с этим деятельность, 68.32 Управление недвижимым имуществом за вознаграждение или на договорной основе, 69.20 Деятельность по оказанию услуг в области бухгалтерского учета, по проведению финансового аудита, по налоговому консультированию, 71.12 Деятельность в области инженерных изысканий, инженерно-технического проектирования, управления проектами строительства, выполнения строительного контроля и авторского надзора, предоставление технических консультаций в этих областях, 71.20.62 Экспертиза проектной документации и результатов инженерных изысканий негосударственная, 73.11 Деятельность рекламных агентств, 74.90.22 Деятельность, направленная на установление рыночной или иной стоимости совокупности вещей, составляющих имущество лица, в том числе имущество определенного вида (движимое или недвижимое, в том числе предприятия), 77.32 Аренда и лизинг строительных машин и оборудования, 82.19 Деятельность по фотокопированию и подготовке документов и прочая специализированная вспомогательная деятельность по обеспечению деятельности офиса, 95.12 Ремонт коммуникационного оборудования.
A3: с НДС 1 кв. 2024: ООО "Восток" (с/ф возможна только от другой компании) | B3: 9704061415 | C3: 45323 | D3: 47.19 Торговля розничная прочая в неспециализированных магазинах, 46.69 Торговля оптовая прочими машинами и оборудованием, 46.90 Торговля оптовая неспециализированная, 47.26 Торговля розничная табачными изделиями в специализированных магазинах, 47.41 Торговля розничная компьютерами, периферийными устройствами к ним и программным обеспечением в специализированных магазинах, 73.11 Деятельность рекламных агентств.
A4: с НДС 1 кв. 2024: ООО "Барс" (с/ф возможна только от другой компании) | B4: 9729308752 | C4: 45342 | D4: 46.15.3 Деятельность агентов по оптовой торговле электротоварами и бытовыми электроустановочными изделиями, 43.21 Производство электромонтажных работ, 43.22 Производство санитарно-технических работ, монтаж отопительных систем и систем кондиционирования воздуха, 43.29 Производство прочих строительно-монтажных работ, 43.99.1 Работы гидроизоляционные, 46.19 Деятельность агентов по оптовой торговле универсальным ассортиментом товаров, 46.62 Торговля оптовая станками, 46.69 Торговля оптовая прочими машинами и оборудованием, 46.73.4 Торговля оптовая лакокрасочными материалами, 46.73.5 Торговля оптовая листовым стеклом, 46.73.6 Торговля оптовая прочими строительными материалами и изделиями, 46.74 Торговля оптовая скобяными изделиями, водопроводным и отопительным оборудованием и принадлежностями, 46.74.2 Торговля оптовая водопроводным и отопительным оборудованием и санитарно-технической арматурой, 46.74.3 Торговля оптовая ручными инструментами, 46.90 Торговля оптовая неспециализированная, 47.19 Торговля розничная прочая в неспециализированных магазинах, 47.42 Торговля розничная телекоммуникационным оборудованием, включая розничную торговлю мобильными телефонами, в специализированных магазинах, 47.52 Торговля розничная скобяными изделиями, лакокрасочными материалами и стеклом в специализированных магазинах, 47.52.5 Торговля розничная санитарно-техническим оборудованием в специализированных магазинах, 47.54 Торговля розничная бытовыми электротоварами в специализированных магазинах, 52.10 Деятельность по складированию и хранению, 52.21 Деятельность вспомогательная, связанная с сухопутным транспортом, 52.21.1 Деятельность вспомогательная, связанная с железнодорожным транспортом, 52.21.2 Деятельность вспомогательная, связанная с автомобильным транспортом, 52.24 Транспортная обработка грузов, 52.29 Деятельность вспомогательная прочая, связанная с перевозками, 71.11.1 Деятельность в области архитектуры, связанная с созданием архитектурного объекта, 71.12.1 Деятельность, связанная с инженерно-техническим проектированием, управлением проектами строительства, выполнением строительного контроля и авторского надзора.
A5: с НДС 1 кв. 2024: ООО "Стронг" (с/ф возможна только от другой компании) | B5: 9722001070 | C5: 45355 | D5: 46.90 Торговля оптовая неспециализированная, 01.11.19 Выращивание прочих зерновых культур, 01.12 Выращивание риса, 01.29 Выращивание прочих многолетних культур, 01.61 Предоставление услуг в области растениеводства, 01.63 Деятельность сельскохозяйственная после сбора урожая, 25.12 Производство металлических дверей и окон, 33.14 Ремонт электрического оборудования, 33.20 Монтаж промышленных машин и оборудования, 38.11 Сбор неопасных отходов, 38.12 Сбор опасных отходов, 38.21 Обработка и утилизация неопасных отходов, 38.22 Обработка и утилизация опасных отходов, 41.20 Строительство жилых и нежилых зданий, 42.99 Строительство прочих инженерных сооружений, не включенных в другие группировки, 43.11 Разборка и снос зданий, 43.12 Подготовка строительной площадки, 43.13 Разведочное бурение, 43.21 Производство электромонтажных работ, 43.22 Производство санитарно-технических работ, монтаж отопительных систем и систем кондиционирования воздуха, 43.29 Производство прочих строительно-монтажных работ, 43.31 Производство штукатурных работ, 43.32 Работы столярные и плотничные, 43.33 Работы по устройству покрытий полов и облицовке стен, 43.34 Производство малярных и стекольных работ, 43.39 Производство прочих отделочных и завершающих работ, 43.91 Производство кровельных работ, 43.99 Работы строительные специализированные прочие, не включенные в другие группировки, 43.99.5 Работы по монтажу стальных строительных конструкций, 46.49.33 Торговля оптовая писчебумажными и канцелярскими товарами, 46.65 Торговля оптовая офисной мебелью, 46.71 Торговля оптовая твердым, жидким и газообразным топливом и подобными продуктами, 46.72 Торговля оптовая металлами и металлическими рудами, 46.73 Торговля оптовая лесоматериалами, строительными материалами и санитарно-техническим оборудованием, 46.74 Торговля оптовая скобяными изделиями, водопроводным и отопительным оборудованием и принадлежностями, 47.91.2 Торговля розничная, осуществляемая непосредственно при помощи информационно-коммуникационной сети Интернет, 49.41 Деятельность автомобильного грузового транспорта, 49.42 Предоставление услуг по перевозкам, 52.10 Деятельность по складированию и хранению, 53.20.31 Деятельность по курьерской доставке различными видами транспорта, 62.02 Деятельность консультативная и работы в области компьютерных технологий, 63.11 Деятельность по обработке данных, предоставление услуг по размещению информации и связанная с этим деятельность, 71.12 Деятельность в области инженерных изысканий, инженерно-технического проектирования, управления проектами строительства, выполнения строительного контроля и авторского надзора, предоставление технических консультаций в этих областях, 71.20.62 Экспертиза проектной документации и результатов инженерных изысканий негосударственная, 74.90.22 Деятельность, направленная на установление рыночной или иной стоимости совокупности вещей, составляющих имущество лица, в том числе имущество определенного вида (движимое или недвижимое, в том числе предприятия), 77.32 Аренда и лизинг строительных машин и оборудования, 81.10 Деятельность по комплексному обслуживанию помещений, 81.22 Деятельность по чистке и уборке жилых зданий и нежилых помещений прочая, 81.29 Деятельность по чистке и уборке прочая, 81.30 Деятельность по благоустройству ландшафта, 82.19 Деятельность по фотокопированию и подготовке документов и прочая специализированная вспомогательная деятельность по обеспечению деятельности офиса, 82.92 Деятельность по упаковыванию товаров.
A6: без НДС 2 кв. 2024: ООО "Оилтранс" | B6: 9722071416 | C6: 45405 | D6: 46.71 Торговля оптовая твердым, жидким и газообразным топливом и подобными продуктами, 41.20 Строительство жилых и нежилых зданий, 42.11 Строительство автомобильных дорог и автомагистралей, 43.11 Разборка и снос зданий, 43.12 Подготовка строительной площадки, 43.13 Разведочное бурение, 43.21 Производство электромонтажных работ, 43.22 Производство санитарно-технических работ, монтаж отопительных систем и систем кондиционирования воздуха, 43.29 Производство прочих строительно-монтажных работ, 43.31 Производство штукатурных работ, 43.32 Работы столярные и плотничные, 43.33 Работы по устройству покрытий полов и облицовке стен, 43.34 Производство малярных и стекольных работ, 43.39 Производство прочих отделочных и завершающих работ, 43.91 Производство кровельных работ, 43.99 Работы строительные специализированные прочие, не включенные в другие группировки, 45.11 Торговля легковыми автомобилями и грузовыми автомобилями малой грузоподъемности, 45.19 Торговля прочими автотранспортными средствами, 45.20 Техническое обслуживание и ремонт автотранспортных средств, 45.31 Торговля оптовая автомобильными деталями, узлами и принадлежностями, 46.62 Торговля оптовая станками, 46.66 Торговля оптовая прочей офисной техникой и оборудованием, 46.69 Торговля оптовая прочими машинами и оборудованием, 46.73 Торговля оптовая лесоматериалами, строительными материалами и санитарно-техническим оборудованием, 46.74 Торговля оптовая скобяными изделиями, водопроводным и отопительным оборудованием и принадлежностями, 46.90 Торговля оптовая неспециализированная, 47.19 Торговля розничная прочая в неспециализированных магазинах, 47.71 Торговля розничная одеждой в специализированных магазинах, 47.72 Торговля розничная обувью и изделиями из кожи в специализированных магазинах, 47.73 Торговля розничная лекарственными средствами в специализированных магазинах (аптеках), 47.99 Торговля розничная прочая вне магазинов, палаток, рынков, 49.41 Деятельность автомобильного грузового транспорта, 49.42 Предоставление услуг по перевозкам, 52.10 Деятельность по складированию и хранению, 52.21 Деятельность вспомогательная, связанная с сухопутным транспортом, 52.24 Транспортная обработка грузов, 52.29 Деятельность вспомогательная прочая, связанная с перевозками, 53.20 Деятельность почтовой связи прочая и курьерская деятельность, 62.09 Деятельность, связанная с использованием вычислительной техники и информационных технологий, прочая, 81.10 Деятельность по комплексному обслуживанию помещений, 81.21 Деятельность по общей уборке зданий, 81.22 Деятельность по чистке и уборке жилых зданий и нежилых помещений прочая, 81.29 Деятельность по чистке и уборке прочая, 82.92 Деятельность по упаковыванию товаров.
A7: с НДС 2 кв. 2024: ООО "Керамик групп" (с/ф возможна только от другой компании) | B7: 9724036946 | C7: 45401 | D7: 41.20 Строительство жилых и нежилых зданий, 42.21 Строительство инженерных коммуникаций для водоснабжения и водоотведения, газоснабжения, 43.11 Разборка и снос зданий, 43.99 Работы строительные специализированные прочие, не включенные в другие группировки, 46.73 Торговля оптовая лесоматериалами, строительными материалами и санитарно-техническим оборудованием, 73.11 Деятельность рекламных агентств, 96.09 Предоставление прочих персональных услуг, не включенных в другие группировки.
A8: без НДС 3 кв. 2024: ООО "Феникс" | B8: 9707031271 | C8: 45483 | D8: 43.11 Разборка и снос зданий, 43.12 Подготовка строительной площадки, 49.41 Деятельность автомобильного грузового транспорта, 49.42 Предоставление услуг по перевозкам, 81.21 Деятельность по общей уборке зданий
A9: с НДС 3 кв. 2024: ООО "Томса" (с/ф возможна только от другой компании) | B9: 7751285120 | C9: 45534 | D9: 82.92 Деятельность по упаковыванию товаров, 41.20 Строительство жилых и нежилых зданий, 42.11 Строительство автомобильных дорог и автомагистралей, 42.12 Строительство железных дорог и метро, 42.13 Строительство мостов и тоннелей, 43.11 Разборка и снос зданий, 43.12 Подготовка строительной площадки, 43.13 Разведочное бурение, 43.21 Производство электромонтажных работ, 43.22 Производство санитарно-технических работ, монтаж отопительных систем и систем кондиционирования воздуха, 43.29 Производство прочих строительно-монтажных работ, 43.31 Производство штукатурных работ, 43.32 Работы столярные и плотничные, 43.33 Работы по устройству покрытий полов и облицовке стен, 43.34 Производство малярных и стекольных работ, 43.39 Производство прочих отделочных и завершающих работ, 43.91 Производство кровельных работ, 43.99 Работы строительные специализированные прочие, не включенные в другие группировки, 45.11 Торговля легковыми автомобилями и грузовыми автомобилями малой грузоподъемности, 45.19 Торговля прочими автотранспортными средствами, 45.20 Техническое обслуживание и ремонт автотранспортных средств, 45.31 Торговля оптовая автомобильными деталями, узлами и принадлежностями, 46.62 Торговля оптовая станками, 46.66 Торговля оптовая прочей офисной техникой и оборудованием, 46.69 Торговля оптовая прочими машинами и оборудованием, 46.71 Торговля оптовая твердым, жидким и газообразным топливом и подобными продуктами, 46.73 Торговля оптовая лесоматериалами, строительными материалами и санитарно-техническим оборудованием, 46.74 Торговля оптовая скобяными изделиями, водопроводным и отопительным оборудованием и принадлежностями, 46.90 Торговля оптовая неспециализированная, 47.19 Торговля розничная прочая в неспециализированных магазинах, 47.71 Торговля розничная одеждой в специализированных магазинах, 47.72 Торговля розничная обувью и изделиями из кожи в специализированных магазинах, 47.99 Торговля розничная прочая вне магазинов, палаток, рынков, 49.41 Деятельность автомобильного грузового транспорта, 49.42 Предоставление услуг по перевозкам, 52.10 Деятельность по складированию и хранению, 52.21 Деятельность вспомогательная, связанная с сухопутным транспортом, 52.24 Транспортная обработка грузов, 52.29 Деятельность вспомогательная прочая, связанная с перевозками, 53.20 Деятельность почтовой связи прочая и курьерская деятельность, 62.09 Деятельность, связанная с использованием вычислительной техники и информационных технологий, прочая, 81.10 Деятельность по комплексному обслуживанию помещений, 81.21 Деятельность по общей уборке зданий, 81.22 Деятельность по чистке и уборке жилых зданий и нежилых помещений прочая, 81.29 Деятельность по чистке и уборке прочая.
A10: без НДС 4 кв. 2024: ООО "ГиперДрайв" | B10: 9724192399 | C10: 45572 | D10: 9.41.3 Аренда грузового автомобильного транспорта с водителем, 49.42 Предоставление услуг по перевозкам, 52.10 Деятельность по складированию и хранению, 52.29 Деятельность вспомогательная, прочая, связанная с перевозками, 53.20 Деятельность почтовой связи прочая и курьерская деятельность, 77.11 Аренда и лизинг легковых автомобилей и легких автотранспортных средств
A11: с НДС 4 кв. 2024: ООО "Шпатл-Инко" (с/ф возможна только от другой компании) | B11: 7733434210 | C11: 45607 | D11: 43.29 Производство прочих строительно-монтажных работ, 41.10 Разработка строительных проектов, 41.20 Строительство жилых и нежилых зданий, 42.11 Строительство автомобильных дорог и автомагистралей, 43.11 Разборка и снос зданий, 43.12 Подготовка строительной площадки, 43.13 Разведочное бурение, 43.21 Производство электромонтажных работ, 43.22 Производство санитарно-технических работ, монтаж отопительных систем и систем кондиционирования воздуха, 43.31 Производство штукатурных работ, 43.32 Работы столярные и плотничные, 43.33 Работы по устройству покрытий полов и облицовке стен, 43.34 Производство малярных и стекольных работ, 43.39 Производство прочих отделочных и завершающих работ, 43.91 Производство кровельных работ, 43.99 Работы строительные специализированные прочие, не включенные в другие группировки, 45.11 Торговля легковыми автомобилями и грузовыми автомобилями малой грузоподъемности, 45.19 Торговля прочими автотранспортными средствами, 45.20 Техническое обслуживание и ремонт автотранспортных средств, 45.31 Торговля оптовая автомобильными деталями, узлами и принадлежностями, 46.62 Торговля оптовая станками, 46.66 Торговля оптовая прочей офисной техникой и оборудованием, 46.69 Торговля оптовая прочими машинами и оборудованием, 46.71 Торговля оптовая твердым, жидким и газообразным топливом и подобными продуктами, 46.73 Торговля оптовая лесоматериалами, строительными материалами и санитарно-техническим оборудованием, 46.74 Торговля оптовая скобяными изделиями, водопроводным и отопительным оборудованием и принадлежностями, 46.90 Торговля оптовая неспециализированная, 49.41 Деятельность автомобильного грузового транспорта, 49.42 Предоставление услуг по перевозкам, 52.10 Деятельность по складированию и хранению, 52.21 Деятельность вспомогательная, связанная с сухопутным транспортом, 52.24 Транспортная обработка грузов, 52.29 Деятельность вспомогательная прочая, связанная с перевозками, 81.10 Деятельность по комплексному обслуживанию помещений, 81.21 Деятельность по общей уборке зданий, 81.22 Деятельность по чистке и уборке жилых зданий и нежилых помещений прочая, 81.29 Деятельность по чистке и уборке прочая.
A12: с НДС 4 кв. 2024: ООО "Акцент" (с/ф возможна только от другой компании) | B12: 7730316120 | C12: 45643 | D12: 46.74 Торговля оптовая скобяными изделиями, водопроводным и отопительным оборудованием и принадлежностями, 41.20 Строительство жилых и нежилых зданий, 43.11 Разборка и снос зданий, 43.12 Подготовка строительной площадки, 43.21 Производство электромонтажных работ, 43.22 Производство санитарно-технических работ, монтаж отопительных систем и систем кондиционирования воздуха, 43.29 Производство прочих строительно-монтажных работ, 43.32 Работы столярные и плотничные, 43.33 Работы по устройству покрытий полов и облицовке стен, 43.34 Производство малярных и стекольных работ, 43.39 Производство прочих отделочных и завершающих работ, 43.91 Производство кровельных работ, 43.99 Работы строительные специализированные прочие, не включенные в другие группировки, 46.73 Торговля оптовая лесоматериалами, строительными материалами и санитарно-техническим оборудованием, 46.90 Торговля оптовая неспециализированная, 47.52.7 Торговля розничная строительными материалами, не включенными в другие группировки, в специализированных магазинах, 49.41 Деятельность автомобильного грузового транспорта, 49.42 Предоставление услуг по перевозкам, 62.01 Разработка компьютерного программного обеспечения, 62.02 Деятельность консультативная и работы в области компьютерных технологий, 62.03 Деятельность по управлению компьютерным оборудованием, 62.09 Деятельность, связанная с использованием вычислительной техники и информационных технологий, прочая, 73.11 Деятельность рекламных агентств, 73.20 Исследование конъюнктуры рынка и изучение общественного мнения, 81.10 Деятельность по комплексному обслуживанию помещений, 81.22 Деятельность по чистке и уборке жилых зданий и нежилых помещений прочая.
A59: НДС:
A60: Да
A61: Нет
